2018-09-25 22:43:44,249 [Dummy-2:824] [django.db.backends:111] [utils:execute] [DEBUG]- (0.016) 
            SELECT name, type FROM sqlite_master
            WHERE type in ('table', 'view') AND NOT name='sqlite_sequence'
            ORDER BY name; args=None
2018-09-25 22:43:44,249 [Dummy-2:824] [django.db.backends:111] [utils:execute] [DEBUG]- (0.000) SELECT "django_migrations"."app", "django_migrations"."name" FROM "django_migrations"; args=()
2018-09-25 22:43:51,875 [Dummy-2:4744] [django.db.backends:111] [utils:execute] [DEBUG]- (0.000) 
            SELECT name, type FROM sqlite_master
            WHERE type in ('table', 'view') AND NOT name='sqlite_sequence'
            ORDER BY name; args=None
2018-09-25 22:43:51,890 [Dummy-2:4744] [django.db.backends:111] [utils:execute] [DEBUG]- (0.000) SELECT "django_migrations"."app", "django_migrations"."name" FROM "django_migrations"; args=()
2018-09-25 22:43:55,341 [Thread-3:7980] [django.db.backends:111] [utils:execute] [DEBUG]- (0.000) SELECT "auth_user"."id", "auth_user"."password", "auth_user"."last_login", "auth_user"."is_superuser", "auth_user"."username", "auth_user"."first_name", "auth_user"."last_name", "auth_user"."email", "auth_user"."is_staff", "auth_user"."is_active", "auth_user"."date_joined" FROM "auth_user" WHERE "auth_user"."id" = 1; args=(1,)
2018-09-25 22:43:55,556 [Thread-3:7980] [django.request:228] [log:log_response] [ERROR]- Internal Server Error: /index/
Traceback (most recent call last):
  File "E:\djan\venv\lib\site-packages\django\core\handlers\exception.py", line 34, in inner
    response = get_response(request)
  File "E:\djan\venv\lib\site-packages\django\core\handlers\base.py", line 126, in _get_response
    response = self.process_exception_by_middleware(e, request)
  File "E:\djan\venv\lib\site-packages\django\core\handlers\base.py", line 124, in _get_response
    response = wrapped_callback(request, *callback_args, **callback_kwargs)
  File "E:\djan\rgc\views.py", line 17, in index
    print(4/0)
ZeroDivisionError: division by zero
2018-09-25 22:43:55,604 [Thread-3:7980] [django.server:124] [basehttp:log_message] [ERROR]- "GET /index/ HTTP/1.1" 500 81251
2018-09-25 22:45:27,297 [Dummy-2:10940] [django.db.backends:111] [utils:execute] [DEBUG]- (0.000) 
            SELECT name, type FROM sqlite_master
            WHERE type in ('table', 'view') AND NOT name='sqlite_sequence'
            ORDER BY name; args=None
2018-09-25 22:45:27,312 [Dummy-2:10940] [django.db.backends:111] [utils:execute] [DEBUG]- (0.000) SELECT "django_migrations"."app", "django_migrations"."name" FROM "django_migrations"; args=()
2018-09-25 22:45:32,176 [Thread-4:3740] [django.db.backends:111] [utils:execute] [DEBUG]- (0.000) SELECT "auth_user"."id", "auth_user"."password", "auth_user"."last_login", "auth_user"."is_superuser", "auth_user"."username", "auth_user"."first_name", "auth_user"."last_name", "auth_user"."email", "auth_user"."is_staff", "auth_user"."is_active", "auth_user"."date_joined" FROM "auth_user" WHERE "auth_user"."id" = 1; args=(1,)
2018-09-25 22:45:32,375 [Thread-4:3740] [django.request:228] [log:log_response] [ERROR]- Internal Server Error: /index/
Traceback (most recent call last):
  File "E:\djan\venv\lib\site-packages\django\core\handlers\exception.py", line 34, in inner
    response = get_response(request)
  File "E:\djan\venv\lib\site-packages\django\core\handlers\base.py", line 126, in _get_response
    response = self.process_exception_by_middleware(e, request)
  File "E:\djan\venv\lib\site-packages\django\core\handlers\base.py", line 124, in _get_response
    response = wrapped_callback(request, *callback_args, **callback_kwargs)
  File "E:\djan\rgc\views.py", line 17, in index
    print(4/0)
ZeroDivisionError: division by zero
2018-09-25 22:45:32,430 [Thread-4:3740] [django.server:124] [basehttp:log_message] [ERROR]- "GET /index/ HTTP/1.1" 500 81251
2018-09-25 22:46:19,205 [Thread-3:11000] [django.request:228] [log:log_response] [ERROR]- Internal Server Error: /index/
Traceback (most recent call last):
  File "E:\djan\venv\lib\site-packages\django\core\handlers\exception.py", line 34, in inner
    response = get_response(request)
  File "E:\djan\venv\lib\site-packages\django\core\handlers\base.py", line 126, in _get_response
    response = self.process_exception_by_middleware(e, request)
  File "E:\djan\venv\lib\site-packages\django\core\handlers\base.py", line 124, in _get_response
    response = wrapped_callback(request, *callback_args, **callback_kwargs)
  File "E:\djan\rgc\views.py", line 17, in index
    print(4/0)
ZeroDivisionError: division by zero
2018-09-25 22:47:08,108 [Thread-3:11004] [django.request:228] [log:log_response] [ERROR]- Internal Server Error: /index/
Traceback (most recent call last):
  File "E:\djan\venv\lib\site-packages\django\core\handlers\exception.py", line 34, in inner
    response = get_response(request)
  File "E:\djan\venv\lib\site-packages\django\core\handlers\base.py", line 126, in _get_response
    response = self.process_exception_by_middleware(e, request)
  File "E:\djan\venv\lib\site-packages\django\core\handlers\base.py", line 124, in _get_response
    response = wrapped_callback(request, *callback_args, **callback_kwargs)
  File "E:\djan\rgc\views.py", line 17, in index
    print(4/0)
ZeroDivisionError: division by zero
